<?xml version="1.0" ?>
<!-- =================================================================================== -->
<!-- |    This document was autogenerated by xacro from urdf/hand_T42.xacro            | -->
<!-- |    EDITING THIS FILE BY HAND IS NOT RECOMMENDED                                 | -->
<!-- =================================================================================== -->
<robot name="hand_T42_model">
  <link name="world"/>
  <link name="base_link">
    <visual>
      <origin rpy="1.57 -1.57 -1.57" xyz="0.065 0 -0.04"/>
      <geometry>
        <mesh filename="package://t42_gripper_description/meshes/base_link.STL"/>
      </geometry>
      <material name="">
        <color rgba="0.1 0.1 0.1 1"/>
      </material>
    </visual>
    <inertial>
      <origin rpy="0 0 0" xyz="0 0 0"/>
      <mass value="0.1"/>
      <inertia ixx="0.0" ixy="0.0" ixz="0.0" iyy="0.0" iyz="0.0" izz="0.0"/>
    </inertial>
    <!-- <collision>
        <origin rpy="1.57 0 -1.57" xyz="0.06 0.017 0"/>
        <geometry>
          <mesh filename="package://t42_gripper_description/meshes/base_link.STL"/>
        </geometry>
      </collision> -->
  </link>
  <link name="swivel_1">
    <visual>
      <material name="white">
        <color rgba="1.0 1.0 1.0 1.0"/>
      </material>
      <origin rpy="0 1.57 1.57" xyz="-0.016510 0.026 0"/>
      <geometry>
        <mesh filename="package://t42_gripper_description/meshes/swivel_t42.STL" scale="0.001 0.001 0.001"/>
      </geometry>
    </visual>
  </link>
  <link name="finger_1_1">
    <inertial>
      <origin xyz="-0.015875 -0.009000 -0.071550"/>
      <mass value="0.1"/>
      <!-- 0.018485 -->
      <inertia ixx="0.01" ixy="0.0" ixz="0.0" iyy="0.01" iyz="0.0" izz="0.01"/>
    </inertial>
    <visual>
      <material name="white">
        <color rgba="1.0 1.0 1.0 1.0"/>
      </material>
      <origin xyz="-0.015875 -0.009000 -0.071550"/>
      <geometry>
        <mesh filename="package://t42_gripper_description/meshes/proximal_t42.STL" scale="0.025400 0.025400 0.025400"/>
      </geometry>
    </visual>
    <collision>
      <origin xyz="-0.015875 -0.009000 -0.071550"/>
      <geometry>
        <mesh filename="package://t42_gripper_description/meshes/proximal_t42.STL" scale="0.025400 0.025400 0.025400"/>
      </geometry>
    </collision>
  </link>
  <link name="finger_1_2">
    <inertial>
      <origin xyz="-0.015875 -0.011709 -0.048006"/>
      <mass value="0.1"/>
      <!-- 0.02369 -->
      <inertia ixx="0.01" ixy="0.0" ixz="0.0" iyy="0.01" iyz="0.0" izz="0.01"/>
    </inertial>
    <visual>
      <material name="green">
        <color rgba="0.1 1.0 0.1 1.0"/>
      </material>
      <origin xyz="-0.0 -0.0 -0.0"/>
      <!-- <origin xyz="-0.015875 -0.011709 -0.048006" /> -->
      <!-- Pointed distal tips -->
      <geometry>
        <mesh filename="package://t42_gripper_description/meshes/distal_round_t42.STL" scale="0.001 0.001 0.001"/>
        <!-- <mesh filename="package://t42_gripper_description/meshes/distal_t42.STL" scale="0.025400 0.025400 0.025400" /> -->
        <!-- Pointed distal tips -->
      </geometry>
    </visual>
    <collision>
      <origin xyz="-0.0 -0.0 -0.0"/>
      <geometry>
        <mesh filename="package://t42_gripper_description/meshes/distal_round_t42.STL" scale="0.001 0.001 0.001"/>
      </geometry>
    </collision>
  </link>
  <link name="swivel_2">
    <visual>
      <material name="white">
        <color rgba="1.0 1.0 1.0 1.0"/>
      </material>
      <origin rpy="0 1.57 1.57" xyz="-0.016510 -0.026 0"/>
      <geometry>
        <mesh filename="package://t42_gripper_description/meshes/swivel_t42.STL" scale="0.001 0.001 0.001"/>
      </geometry>
    </visual>
  </link>
  <link name="finger_2_1">
    <inertial>
      <origin xyz="-0.015875 -0.009000 -0.071550"/>
      <mass value="0.1"/>
      <inertia ixx="0.01" ixy="0.0" ixz="0.0" iyy="0.01" iyz="0.0" izz="0.01"/>
    </inertial>
    <visual>
      <material name="white">
        <color rgba="1.0 1.0 1.0 1.0"/>
      </material>
      <origin xyz="-0.015875 -0.009000 -0.071550"/>
      <geometry>
        <mesh filename="package://t42_gripper_description/meshes/proximal_t42.STL" scale="0.025400 0.025400 0.025400"/>
      </geometry>
    </visual>
    <collision>
      <origin xyz="-0.015875 -0.009000 -0.071550"/>
      <geometry>
        <mesh filename="package://t42_gripper_description/meshes/proximal_t42.STL" scale="0.025400 0.025400 0.025400"/>
      </geometry>
    </collision>
  </link>
  <link name="finger_2_2">
    <inertial>
      <origin xyz="-0.015875 -0.011709 -0.048006"/>
      <mass value="0.1"/>
      <inertia ixx="0.01" ixy="0.0" ixz="0.0" iyy="0.01" iyz="0.0" izz="0.01"/>
    </inertial>
    <visual>
      <material name="orange">
        <color rgba="0.9 0.3 0.1 1.0"/>
      </material>
      <origin xyz="0 0 0"/>
      <geometry>
        <mesh filename="package://t42_gripper_description/meshes/distal_round_t42.STL" scale="0.001 0.001 0.001"/>
      </geometry>
    </visual>
    <collision>
      <origin xyz="0 0 0"/>
      <geometry>
        <mesh filename="package://t42_gripper_description/meshes/distal_round_t42.STL" scale="0.001 0.001 0.001"/>
      </geometry>
    </collision>
  </link>
  <joint name="world_to_base" type="prismatic">
    <origin rpy="0 0 0" xyz="-0.06 0.000000 0.2"/>
    <parent link="world"/>
    <child link="base_link"/>
    <axis xyz="0 0 1"/>
    <limit effort="1000.0" lower="-100." upper="100." velocity="1"/>
  </joint>
  <joint name="base_link_to_swivel_1" type="fixed">
    <origin rpy="0 0 0" xyz="0 0.000000 0.000000"/>
    <parent link="base_link"/>
    <child link="swivel_1"/>
  </joint>
  <joint name="base_to_finger_1_1" type="revolute">
    <origin rpy="-1.57079632679 1.57079632679 0" xyz="-0.016510 -0.026 0.000000"/>
    <parent link="base_link"/>
    <child link="finger_1_1"/>
    <limit effort="10000" lower="0.0" upper="3.0" velocity="2"/>
    <axis xyz="1 0 0"/>
    <dynamics damping="7.0" friction="0.0"/>
  </joint>
  <joint name="finger_1_1_to_finger_1_2" type="revolute">
    <origin rpy="0 0 0" xyz="0.000000 0.000000 -0.062551"/>
    <parent link="finger_1_1"/>
    <child link="finger_1_2"/>
    <limit effort="10000" lower="0.0" upper="1.57" velocity="2"/>
    <axis xyz="1 0 0"/>
    <dynamics damping="7.0" friction="0.0"/>
  </joint>
  <joint name="base_link_to_swivel_2" type="fixed">
    <origin rpy="0 0 0" xyz="0 0.000000 0.000000"/>
    <parent link="base_link"/>
    <child link="swivel_2"/>
  </joint>
  <joint name="base_to_finger_2_1" type="revolute">
    <origin rpy="1.57079632679 -1.57079632679 0" xyz="-0.016510 0.026 0.0000"/>
    <parent link="base_link"/>
    <child link="finger_2_1"/>
    <limit effort="10000" lower="0.0" upper="3.0" velocity="2"/>
    <axis xyz="1 0 0"/>
    <dynamics damping="7.0" friction="0.0"/>
  </joint>
  <joint name="finger_2_1_to_finger_2_2" type="revolute">
    <origin rpy="0 0 0" xyz="0.000000 0.000000 -0.062551"/>
    <parent link="finger_2_1"/>
    <child link="finger_2_2"/>
    <limit effort="10000" lower="0.0" upper="1.57" velocity="2"/>
    <axis xyz="1 0 0"/>
    <dynamics damping="7.0" friction="0.0"/>
  </joint>
  <!-- Transmissions -->
  <transmission name="finger1_2_trans" type="SimpleTransmission">
    <type>transmission_interface/SimpleTransmission</type>
    <actuator name="$finger12_motor">
      <mechanicalReduction>1</mechanicalReduction>
    </actuator>
    <joint name="base_to_finger_1_1">
      <hardwareInterface>hardware_interface/EffortJointInterface</hardwareInterface>
    </joint>
  </transmission>
  <transmission name="finger1_3_trans" type="SimpleTransmission">
    <type>transmission_interface/SimpleTransmission</type>
    <actuator name="$finger13_motor">
      <mechanicalReduction>1</mechanicalReduction>
    </actuator>
    <joint name="finger_1_1_to_finger_1_2">
      <hardwareInterface>hardware_interface/EffortJointInterface</hardwareInterface>
    </joint>
  </transmission>
  <transmission name="finger2_2_trans" type="SimpleTransmission">
    <type>transmission_interface/SimpleTransmission</type>
    <actuator name="$finger22_motor">
      <mechanicalReduction>1</mechanicalReduction>
    </actuator>
    <joint name="base_to_finger_2_1">
      <hardwareInterface>hardware_interface/EffortJointInterface</hardwareInterface>
    </joint>
  </transmission>
  <transmission name="finger2_3_trans" type="SimpleTransmission">
    <type>transmission_interface/SimpleTransmission</type>
    <actuator name="$finger23_motor">
      <mechanicalReduction>1</mechanicalReduction>
    </actuator>
    <joint name="finger_2_1_to_finger_2_2">
      <hardwareInterface>hardware_interface/EffortJointInterface</hardwareInterface>
    </joint>
  </transmission>
</robot>
